2020-10-25 17:36:59,304: INFO: discord: Starting up the client
2020-10-25 17:36:59,388: WARNING: discord.client: PyNaCl is not installed, voice will NOT be supported
2020-10-25 17:36:59,392: INFO: discord.client: logging in using static token
2020-10-25 17:36:59,930: INFO: discord.gateway: Shard ID None has sent the IDENTIFY payload.
2020-10-25 17:37:00,052: INFO: discord.gateway: Shard ID None has connected to Gateway: ["gateway-prd-main-f7nd",{"micros":46232,"calls":["discord-sessions-prd-2-74",{"micros":42820,"calls":["start_session",{"micros":35037,"calls":["api-prd-main-dknq",{"micros":32344,"calls":["get_user",{"micros":3423},"add_authorized_ip",{"micros":2718},"get_guilds",{"micros":1423},"coros_wait",{"micros":1}]}]},"guilds_connect",{"micros":1,"calls":[]},"presence_connect",{"micros":2082,"calls":[]}]}]}] (Session ID: 245036eaa99a197a0adbe97d103ff452).
2020-10-25 17:37:01,679: INFO: discord: DIRECT: ericl16384#4692: !play
2020-10-25 17:37:01,681: ERROR: discord: on_message error:
args: (<Message id=770083513918816307 channel=<DMChannel id=768683999408554014 recipient=<User id=472882667382112256 name='ericl16384' discriminator='4692' bot=False>> type=<MessageType.default: 0> author=<User id=472882667382112256 name='ericl16384' discriminator='4692' bot=False> flags=<MessageFlags value=0>>,)
kwargs: {}
Traceback (most recent call last):
  File "C:\Users\eric\AppData\Local\Programs\Python\Python38\lib\site-packages\discord\client.py", line 333, in _run_event
    await coro(*args, **kwargs)
  File "c:\Users\eric\Desktop\Programming\Python\Discord\bot.py", line 144, in on_message
    data = cmd.run(message)
  File "c:\Users\eric\Desktop\Programming\Python\Discord\discordUtil.py", line 316, in run
    return self.doDataLogic(cmds[i]["data"], message=message)
  File "c:\Users\eric\Desktop\Programming\Python\Discord\discordUtil.py", line 245, in doDataLogic
    return self.continueIteratorSession(message)
  File "c:\Users\eric\Desktop\Programming\Python\Discord\discordUtil.py", line 179, in continueIteratorSession
    return self.iteratorSessions[id].send(message)
TypeError: can't send non-None value to a just-started generator
2020-10-25 17:37:05,466: INFO: discord: DIRECT: ericl16384#4692: .
2020-10-25 17:37:05,467: ERROR: discord: on_message error:
args: (<Message id=770083529970417684 channel=<DMChannel id=768683999408554014 recipient=<User id=472882667382112256 name='ericl16384' discriminator='4692' bot=False>> type=<MessageType.default: 0> author=<User id=472882667382112256 name='ericl16384' discriminator='4692' bot=False> flags=<MessageFlags value=0>>,)
kwargs: {}
Traceback (most recent call last):
  File "C:\Users\eric\AppData\Local\Programs\Python\Python38\lib\site-packages\discord\client.py", line 333, in _run_event
    await coro(*args, **kwargs)
  File "c:\Users\eric\Desktop\Programming\Python\Discord\bot.py", line 144, in on_message
    data = cmd.run(message)
  File "c:\Users\eric\Desktop\Programming\Python\Discord\discordUtil.py", line 276, in run
    ans = self.continueIteratorSession(message)
  File "c:\Users\eric\Desktop\Programming\Python\Discord\discordUtil.py", line 179, in continueIteratorSession
    return self.iteratorSessions[id].send(message)
TypeError: can't send non-None value to a just-started generator
2020-10-25 17:40:42,565: WARNING: discord.gateway: Shard ID None has stopped responding to the gateway. Closing and restarting.
2020-10-25 17:40:42,569: INFO: discord.gateway: Timed out receiving packet. Attempting a reconnect.
2020-10-25 17:40:42,570: INFO: discord.client: Got a request to RESUME the websocket.
2020-10-25 17:40:42,583: ERROR: discord.client: Attempting a reconnect in 1.22s
Traceback (most recent call last):
  File "C:\Users\eric\AppData\Local\Programs\Python\Python38\lib\site-packages\aiohttp\connector.py", line 964, in _create_direct_connection
    hosts = await asyncio.shield(self._resolve_host(
  File "C:\Users\eric\AppData\Local\Programs\Python\Python38\lib\site-packages\aiohttp\connector.py", line 829, in _resolve_host
    addrs = await \
  File "C:\Users\eric\AppData\Local\Programs\Python\Python38\lib\site-packages\aiohttp\resolver.py", line 29, in resolve
    infos = await self._loop.getaddrinfo(
  File "C:\Users\eric\AppData\Local\Programs\Python\Python38\lib\asyncio\base_events.py", line 825, in getaddrinfo
    return await self.run_in_executor(
  File "C:\Users\eric\AppData\Local\Programs\Python\Python38\lib\concurrent\futures\thread.py", line 57, in run
    result = self.fn(*self.args, **self.kwargs)
  File "C:\Users\eric\AppData\Local\Programs\Python\Python38\lib\socket.py", line 918, in getaddrinfo
    for res in _socket.getaddrinfo(host, port, family, type, proto, flags):
socket.gaierror: [Errno 11001] getaddrinfo failed

The above exception was the direct cause of the following exception:

Traceback (most recent call last):
  File "C:\Users\eric\AppData\Local\Programs\Python\Python38\lib\site-packages\discord\client.py", line 548, in connect
    self.ws = await asyncio.wait_for(coro, timeout=60.0)
  File "C:\Users\eric\AppData\Local\Programs\Python\Python38\lib\asyncio\tasks.py", line 491, in wait_for
    return fut.result()
  File "C:\Users\eric\AppData\Local\Programs\Python\Python38\lib\site-packages\discord\gateway.py", line 305, in from_client
    gateway = gateway or await client.http.get_gateway()
  File "C:\Users\eric\AppData\Local\Programs\Python\Python38\lib\site-packages\discord\http.py", line 910, in get_gateway
    data = await self.request(Route('GET', '/gateway'))
  File "C:\Users\eric\AppData\Local\Programs\Python\Python38\lib\site-packages\discord\http.py", line 185, in request
    async with self.__session.request(method, url, **kwargs) as r:
  File "C:\Users\eric\AppData\Local\Programs\Python\Python38\lib\site-packages\aiohttp\client.py", line 1012, in __aenter__
    self._resp = await self._coro
  File "C:\Users\eric\AppData\Local\Programs\Python\Python38\lib\site-packages\aiohttp\client.py", line 480, in _request
    conn = await self._connector.connect(
  File "C:\Users\eric\AppData\Local\Programs\Python\Python38\lib\site-packages\aiohttp\connector.py", line 523, in connect
    proto = await self._create_connection(req, traces, timeout)
  File "C:\Users\eric\AppData\Local\Programs\Python\Python38\lib\site-packages\aiohttp\connector.py", line 858, in _create_connection
    _, proto = await self._create_direct_connection(
  File "C:\Users\eric\AppData\Local\Programs\Python\Python38\lib\site-packages\aiohttp\connector.py", line 971, in _create_direct_connection
    raise ClientConnectorError(req.connection_key, exc) from exc
aiohttp.client_exceptions.ClientConnectorError: Cannot connect to host discord.com:443 ssl:default [getaddrinfo failed]
2020-10-25 17:41:25,129: INFO: discord.gateway: Shard ID None has sent the RESUME payload.
2020-10-25 17:41:25,201: INFO: discord.gateway: Shard ID None session has been invalidated.
2020-10-25 17:41:25,272: INFO: discord.client: Got a request to IDENTIFY the websocket.
2020-10-25 18:48:01,444: ERROR: discord.client: Attempting a reconnect in 1.25s
Traceback (most recent call last):
  File "C:\Users\eric\AppData\Local\Programs\Python\Python38\lib\site-packages\discord\client.py", line 548, in connect
    self.ws = await asyncio.wait_for(coro, timeout=60.0)
  File "C:\Users\eric\AppData\Local\Programs\Python\Python38\lib\asyncio\tasks.py", line 498, in wait_for
    raise exceptions.TimeoutError()
asyncio.exceptions.TimeoutError
2020-10-25 18:48:03,924: INFO: discord.gateway: Shard ID None has sent the RESUME payload.
2020-10-25 18:48:28,781: WARNING: discord.gateway: Can't keep up, shard ID None websocket is 24.9s behind.
2020-10-25 18:48:28,782: INFO: discord.gateway: Shard ID None session has been invalidated.
2020-10-25 18:48:28,869: INFO: discord.client: Got a request to IDENTIFY the websocket.
2020-10-25 18:48:34,205: INFO: discord.gateway: Shard ID None has sent the IDENTIFY payload.
2020-10-25 18:48:34,345: INFO: discord.gateway: Shard ID None has connected to Gateway: ["gateway-prd-main-rqps",{"micros":51042,"calls":["discord-sessions-prd-2-51",{"micros":48184,"calls":["start_session",{"micros":36672,"calls":["api-prd-main-jt6t",{"micros":33884,"calls":["get_user",{"micros":3880},"add_authorized_ip",{"micros":1632},"get_guilds",{"micros":4901},"coros_wait",{"micros":1}]}]},"guilds_connect",{"micros":1,"calls":[]},"presence_connect",{"micros":573,"calls":[]}]}]}] (Session ID: b85752cea4c01ecc28711732a1a5e971).
2020-10-25 21:23:06,403: INFO: discord.client: Got a request to RESUME the websocket.
2020-10-25 21:23:06,808: INFO: discord.gateway: Shard ID None has sent the RESUME payload.
2020-10-25 21:23:06,890: INFO: discord.gateway: Shard ID None has successfully RESUMED session b85752cea4c01ecc28711732a1a5e971 under trace ["gateway-prd-main-rb6c",{"micros":6432,"calls":["discord-sessions-prd-2-51",{"micros":14}]}].
2020-10-26 00:01:08,262: INFO: discord.client: Got a request to RESUME the websocket.
2020-10-26 00:01:08,669: INFO: discord.gateway: Shard ID None has sent the RESUME payload.
2020-10-26 00:01:08,750: INFO: discord.gateway: Shard ID None has successfully RESUMED session b85752cea4c01ecc28711732a1a5e971 under trace ["gateway-prd-main-b2sb",{"micros":1575,"calls":["discord-sessions-prd-2-51",{"micros":15}]}].
2020-10-26 00:18:16,356: INFO: discord.client: Got a request to RESUME the websocket.
2020-10-26 00:18:16,777: INFO: discord.gateway: Shard ID None has sent the RESUME payload.
2020-10-26 00:18:16,863: INFO: discord.gateway: Shard ID None has successfully RESUMED session b85752cea4c01ecc28711732a1a5e971 under trace ["gateway-prd-main-532j",{"micros":3414,"calls":["discord-sessions-prd-2-51",{"micros":16}]}].
2020-10-26 02:18:28,801: INFO: discord.client: Got a request to RESUME the websocket.
2020-10-26 02:18:29,180: INFO: discord.gateway: Shard ID None has sent the RESUME payload.
2020-10-26 02:18:29,261: INFO: discord.gateway: Shard ID None has successfully RESUMED session b85752cea4c01ecc28711732a1a5e971 under trace ["gateway-prd-main-q3qc",{"micros":706,"calls":["discord-sessions-prd-2-51",{"micros":12}]}].
2020-10-26 04:53:32,744: INFO: discord.client: Got a request to RESUME the websocket.
2020-10-26 04:53:33,168: INFO: discord.gateway: Shard ID None has sent the RESUME payload.
2020-10-26 04:53:33,247: INFO: discord.gateway: Shard ID None has successfully RESUMED session b85752cea4c01ecc28711732a1a5e971 under trace ["gateway-prd-main-pwhw",{"micros":1635,"calls":["discord-sessions-prd-2-51",{"micros":15}]}].
2020-10-26 06:50:05,776: INFO: discord.gateway: Websocket closed with 1006, attempting a reconnect.
2020-10-26 06:50:05,779: INFO: discord.client: Got a request to RESUME the websocket.
2020-10-26 06:50:06,195: INFO: discord.gateway: Shard ID None has sent the RESUME payload.
2020-10-26 06:50:06,274: INFO: discord.gateway: Shard ID None has successfully RESUMED session b85752cea4c01ecc28711732a1a5e971 under trace ["gateway-prd-main-kk2f",{"micros":5443,"calls":["discord-sessions-prd-2-51",{"micros":14}]}].
2020-10-26 10:31:25,576: INFO: discord.client: Got a request to RESUME the websocket.
2020-10-26 10:31:25,951: INFO: discord.gateway: Shard ID None has sent the RESUME payload.
2020-10-26 10:31:26,036: INFO: discord.gateway: Shard ID None has successfully RESUMED session b85752cea4c01ecc28711732a1a5e971 under trace ["gateway-prd-main-lf78",{"micros":1212,"calls":["discord-sessions-prd-2-51",{"micros":13}]}].
